Workbook

Sheet FUNDED DEALS
A1: 2026 GRAND TOTAL | D1: =SUM(COUNT(C4:C103),COUNT(C106:C205),COUNT(C208:C307),COUNT(C310:C409),COUNT(C412:C511),COUNT(C514:C613),COUNT(C616:C715),COUNT(C718:C817),COUNT(C820:C919))&" units" -> 0 units | G1: =G104+G206+G308+G410+G512+G614+G716+G818+G920 -> 0 | N1: =N104+N206+N308+N410+N512+N614+N716+N818+N920 -> 0 | O1: =O104+O206+O308+O410+O512+O614+O716+O818+O920 -> 0 | R1: =R104+R206+R308+R410+R512+R614+R716+R818+R920 -> 0 | S1: =S104+S206+S308+S410+S512+S614+S716+S818+S920 -> 0 | AC1: =AC104+AC206+AC308+AC410+AC512+AC614+AC716+AC818+AC920 -> 0 | AD1: =AD104+AD206+AD308+AD410+AD512+AD614+AD716+AD818+AD920 -> 0 | AE1: =AE104+AE206+AE308+AE410+AE512+AE614+AE716+AE818+AE920 -> 0 | AJ1: =AJ104+AJ206+AJ308+AJ410+AJ512+AJ614+AJ716+AJ818+AJ920 -> 0 | AK1: =AK104+AK206+AK308+AK410+AK512+AK614+AK716+AK818+AK920 -> 0 | AL1: =AL104+AL206+AL308+AL410+AL512+AL614+AL716+AL818+AL920 -> 0
A2: Deal ID | B2: Parent Deal | C2: Date | D2: Business Name | E2: Lender | F2: Product | G2: Funded / Draw Amount ($) | H2: Factor Rate | I2: Term (bus. days) | J2: Payback ($) | K2: Frequency | L2: Comm % | M2: PSF (% or $) | N2: PSF $ (auto) | O2: Gross Commission ($) | P2: Referral Partner | Q2: Referral % | R2: Referral Fee ($) | S2: Net Comm After Referral ($) | T2: Opener | U2: Opener % | V2: Opener $ | W2: Closer | X2: Closer % | Y2: Closer $ | Z2: Override Rep | AA2: Override % | AB2: Override $ | AC2: Total Rep Payout ($) | AD2: HOUSE NET ($) | AE2: Clawback $ | AF2: Clawback Date | AG2: Opener CB $ | AH2: Closer CB $ | AI2: Override CB $ | AJ2: Rep Clawback $ | AK2: House Clawback $ | AL2: House Net After Clawback ($) | AM2: Commission Status | AN2: Lender Paid Date | AO2: Rep Paid Date | AP2: Est. Renewal (40% in) | AQ2: Deal Status | AR2: Maturity Date | AS2: Notes | AT2: CB Risk | AU2: Lead Source
A3: ▼ APRIL 2026 | AW3: 0 | AX3: 0
A4: =IF(C4<>"","F"&COUNT($C$4:C4),"") | B4: =IF(OR(F4="LOC - INITIAL",F4="CONSOLIDATION - UPFRONT COMM",F4="REVERSE - TOTAL FUNDING"),A4,"") | J4: =IF(AND(G4<>"",H4<>""),G4*H4,"") | N4: =IF(OR(G4="",M4=""),0,IF(M4>100,M4,G4*IF(M4>1,M4/100,M4))) -> 0 | O4: =IF(G4="","",G4*IF(L4="",0,IF(L4>1,L4/100,L4))+N4) | Q4: =IF(P4="","",IFERROR(VLOOKUP(P4,PARTNERS!$A$2:$B$30,2,0),"")) | R4: =IF(O4="","",IF(OR(P4="",Q4=""),0,(O4-N4)*IF(Q4>1,Q4/100,Q4))) | S4: =IF(O4="","",O4-R4) | U4: =IF(T4="","",IFERROR(VLOOKUP(T4,REPS!$A$2:$D$40,2,0),"")) | V4: =IF(O4="","",IF(U4="",0,O4*IF(U4>1,U4/100,U4))) | X4: =IF(W4="","",IFERROR(VLOOKUP(W4,REPS!$A$2:$D$40,3,0),"")) | Y4: =IF(O4="","",IF(X4="",0,O4*IF(X4>1,X4/100,X4))) | AA4: =IF(Z4="","",IFERROR(VLOOKUP(Z4,REPS!$A$2:$D$40,4,0),"")) | AB4: =IF(O4="","",IF(AA4="",0,O4*IF(AA4>1,AA4/100,AA4))) | AC4: =IF(O4="","",V4+Y4+AB4) | AD4: =IF(O4="","",O4-R4-AC4) | AG4: =IF(OR(AE4="",AE4=0),0,AE4*IF(U4="",0,IF(U4>1,U4/100,U4))) -> 0 | AH4: =IF(OR(AE4="",AE4=0),0,AE4*IF(X4="",0,IF(X4>1,X4/100,X4))) -> 0 | AI4: =IF(OR(AE4="",AE4=0),0,AE4*IF(AA4="",0,IF(AA4>1,AA4/100,AA4))) -> 0 | AJ4: =AG4+AH4+AI4 -> 0 | AK4: =IF(OR(AE4="",AE4=0),0,AE4-AJ4) -> 0 | AL4: =IF(AD4="","",AD4-AK4) | AM4: =IF(C4="","","Waiting for payment") | AP4: =IF(OR(C4="",I4="",K4=""),"",IF(K4="Monthly",EDATE(C4,ROUND(I4*SETTINGS!$I$8,0)),WORKDAY(C4,ROUND(I4*SETTINGS!$I$8,0)))) | AQ4: =IF(C4="","",IF(AND(AP4<>"",TODAY()>=AP4),"Refi Ready",IF(TODAY()-C4>=SETTINGS!$I$11,"Prospecting","Performing"))) | AR4: =IF(OR(C4="",I4="",K4=""),"",IF(K4="Monthly",EDATE(C4,I4),WORKDAY(C4,I4))) | AT4: =IF(C4="","",IF(AM4="Clawed Back","CLAWED",IF(TODAY()<=C4+SETTINGS!$I$2,"⚠ AT RISK","SAFE"))) | AW4: =AW3+IF(AND(C4<>"",AO4<>"",OR('REP COMMISSION'!$B$3="",T4='REP COMMISSION'!$B$3,W4='REP COMMISSION'!$B$3,Z4='REP COMMISSION'!$B$3)),1,0) -> 0 | AX4: =AX3+IF(AND(C4<>"",OR(F4="LOC - INITIAL",F4="CONSOLIDATION - UPFRONT COMM",F4="REVERSE - TOTAL FUNDING")),1,0) -> 0
A5: =IF(C5<>"","F"&COUNT($C$4:C5),"") | B5: =IF(OR(F5="LOC - INITIAL",F5="CONSOLIDATION - UPFRONT COMM",F5="REVERSE - TOTAL FUNDING"),A5,"") | J5: =IF(AND(G5<>"",H5<>""),G5*H5,"") | N5: =IF(OR(G5="",M5=""),0,IF(M5>100,M5,G5*IF(M5>1,M5/100,M5))) -> 0 | O5: =IF(G5="","",G5*IF(L5="",0,IF(L5>1,L5/100,L5))+N5) | Q5: =IF(P5="","",IFERROR(VLOOKUP(P5,PARTNERS!$A$2:$B$30,2,0),"")) | R5: =IF(O5="","",IF(OR(P5="",Q5=""),0,(O5-N5)*IF(Q5>1,Q5/100,Q5))) | S5: =IF(O5="","",O5-R5) | U5: =IF(T5="","",IFERROR(VLOOKUP(T5,REPS!$A$2:$D$40,2,0),"")) | V5: =IF(O5="","",IF(U5="",0,O5*IF(U5>1,U5/100,U5))) | X5: =IF(W5="","",IFERROR(VLOOKUP(W5,REPS!$A$2:$D$40,3,0),"")) | Y5: =IF(O5="","",IF(X5="",0,O5*IF(X5>1,X5/100,X5))) | AA5: =IF(Z5="","",IFERROR(VLOOKUP(Z5,REPS!$A$2:$D$40,4,0),"")) | AB5: =IF(O5="","",IF(AA5="",0,O5*IF(AA5>1,AA5/100,AA5))) | AC5: =IF(O5="","",V5+Y5+AB5) | AD5: =IF(O5="","",O5-R5-AC5) | AG5: =IF(OR(AE5="",AE5=0),0,AE5*IF(U5="",0,IF(U5>1,U5/100,U5))) -> 0 | AH5: =IF(OR(AE5="",AE5=0),0,AE5*IF(X5="",0,IF(X5>1,X5/100,X5))) -> 0 | AI5: =IF(OR(AE5="",AE5=0),0,AE5*IF(AA5="",0,IF(AA5>1,AA5/100,AA5))) -> 0 | AJ5: =AG5+AH5+AI5 -> 0 | AK5: =IF(OR(AE5="",AE5=0),0,AE5-AJ5) -> 0 | AL5: =IF(AD5="","",AD5-AK5) | AM5: =IF(C5="","","Waiting for payment") | AP5: =IF(OR(C5="",I5="",K5=""),"",IF(K5="Monthly",EDATE(C5,ROUND(I5*SETTINGS!$I$8,0)),WORKDAY(C5,ROUND(I5*SETTINGS!$I$8,0)))) | AQ5: =IF(C5="","",IF(AND(AP5<>"",TODAY()>=AP5),"Refi Ready",IF(TODAY()-C5>=SETTINGS!$I$11,"Prospecting","Performing"))) | AR5: =IF(OR(C5="",I5="",K5=""),"",IF(K5="Monthly",EDATE(C5,I5),WORKDAY(C5,I5))) | AT5: =IF(C5="","",IF(AM5="Clawed Back","CLAWED",IF(TODAY()<=C5+SETTINGS!$I$2,"⚠ AT RISK","SAFE"))) | AW5: =AW4+IF(AND(C5<>"",AO5<>"",OR('REP COMMISSION'!$B$3="",T5='REP COMMISSION'!$B$3,W5='REP COMMISSION'!$B$3,Z5='REP COMMISSION'!$B$3)),1,0) -> 0 | AX5: =AX4+IF(AND(C5<>"",OR(F5="LOC - INITIAL",F5="CONSOLIDATION - UPFRONT COMM",F5="REVERSE - TOTAL FUNDING")),1,0) -> 0
A6: =IF(C6<>"","F"&COUNT($C$4:C6),"") | B6: =IF(OR(F6="LOC - INITIAL",F6="CONSOLIDATION - UPFRONT COMM",F6="REVERSE - TOTAL FUNDING"),A6,"") | J6: =IF(AND(G6<>"",H6<>""),G6*H6,"") | N6: =IF(OR(G6="",M6=""),0,IF(M6>100,M6,G6*IF(M6>1,M6/100,M6))) -> 0 | O6: =IF(G6="","",G6*IF(L6="",0,IF(L6>1,L6/100,L6))+N6) | Q6: =IF(P6="","",IFERROR(VLOOKUP(P6,PARTNERS!$A$2:$B$30,2,0),"")) | R6: =IF(O6="","",IF(OR(P6="",Q6=""),0,(O6-N6)*IF(Q6>1,Q6/100,Q6))) | S6: =IF(O6="","",O6-R6) | U6: =IF(T6="","",IFERROR(VLOOKUP(T6,REPS!$A$2:$D$40,2,0),"")) | V6: =IF(O6="","",IF(U6="",0,O6*IF(U6>1,U6/100,U6))) | X6: =IF(W6="","",IFERROR(VLOOKUP(W6,REPS!$A$2:$D$40,3,0),"")) | Y6: =IF(O6="","",IF(X6="",0,O6*IF(X6>1,X6/100,X6))) | AA6: =IF(Z6="","",IFERROR(VLOOKUP(Z6,REPS!$A$2:$D$40,4,0),"")) | AB6: =IF(O6="","",IF(AA6="",0,O6*IF(AA6>1,AA6/100,AA6))) | AC6: =IF(O6="","",V6+Y6+AB6) | AD6: =IF(O6="","",O6-R6-AC6) | AG6: =IF(OR(AE6="",AE6=0),0,AE6*IF(U6="",0,IF(U6>1,U6/100,U6))) -> 0 | AH6: =IF(OR(AE6="",AE6=0),0,AE6*IF(X6="",0,IF(X6>1,X6/100,X6))) -> 0 | AI6: =IF(OR(AE6="",AE6=0),0,AE6*IF(AA6="",0,IF(AA6>1,AA6/100,AA6))) -> 0 | AJ6: =AG6+AH6+AI6 -> 0 | AK6: =IF(OR(AE6="",AE6=0),0,AE6-AJ6) -> 0 | AL6: =IF(AD6="","",AD6-AK6) | AM6: =IF(C6="","","Waiting for payment") | AP6: =IF(OR(C6="",I6="",K6=""),"",IF(K6="Monthly",EDATE(C6,ROUND(I6*SETTINGS!$I$8,0)),WORKDAY(C6,ROUND(I6*SETTINGS!$I$8,0)))) | AQ6: =IF(C6="","",IF(AND(AP6<>"",TODAY()>=AP6),"Refi Ready",IF(TODAY()-C6>=SETTINGS!$I$11,"Prospecting","Performing"))) | AR6: =IF(OR(C6="",I6="",K6=""),"",IF(K6="Monthly",EDATE(C6,I6),WORKDAY(C6,I6))) | AT6: =IF(C6="","",IF(AM6="Clawed Back","CLAWED",IF(TODAY()<=C6+SETTINGS!$I$2,"⚠ AT RISK","SAFE"))) | AW6: =AW5+IF(AND(C6<>"",AO6<>"",OR('REP COMMISSION'!$B$3="",T6='REP COMMISSION'!$B$3,W6='REP COMMISSION'!$B$3,Z6='REP COMMISSION'!$B$3)),1,0) -> 0 | AX6: =AX5+IF(AND(C6<>"",OR(F6="LOC - INITIAL",F6="CONSOLIDATION - UPFRONT COMM",F6="REVERSE - TOTAL FUNDING")),1,0) -> 0
A7: =IF(C7<>"","F"&COUNT($C$4:C7),"") | B7: =IF(OR(F7="LOC - INITIAL",F7="CONSOLIDATION - UPFRONT COMM",F7="REVERSE - TOTAL FUNDING"),A7,"") | J7: =IF(AND(G7<>"",H7<>""),G7*H7,"") | N7: =IF(OR(G7="",M7=""),0,IF(M7>100,M7,G7*IF(M7>1,M7/100,M7))) -> 0 | O7: =IF(G7="","",G7*IF(L7="",0,IF(L7>1,L7/100,L7))+N7) | Q7: =IF(P7="","",IFERROR(VLOOKUP(P7,PARTNERS!$A$2:$B$30,2,0),"")) | R7: =IF(O7="","",IF(OR(P7="",Q7=""),0,(O7-N7)*IF(Q7>1,Q7/100,Q7))) | S7: =IF(O7="","",O7-R7) | U7: =IF(T7="","",IFERROR(VLOOKUP(T7,REPS!$A$2:$D$40,2,0),"")) | V7: =IF(O7="","",IF(U7="",0,O7*IF(U7>1,U7/100,U7))) | X7: =IF(W7="","",IFERROR(VLOOKUP(W7,REPS!$A$2:$D$40,3,0),"")) | Y7: =IF(O7="","",IF(X7="",0,O7*IF(X7>1,X7/100,X7))) | AA7: =IF(Z7="","",IFERROR(VLOOKUP(Z7,REPS!$A$2:$D$40,4,0),"")) | AB7: =IF(O7="","",IF(AA7="",0,O7*IF(AA7>1,AA7/100,AA7))) | AC7: =IF(O7="","",V7+Y7+AB7) | AD7: =IF(O7="","",O7-R7-AC7) | AG7: =IF(OR(AE7="",AE7=0),0,AE7*IF(U7="",0,IF(U7>1,U7/100,U7))) -> 0 | AH7: =IF(OR(AE7="",AE7=0),0,AE7*IF(X7="",0,IF(X7>1,X7/100,X7))) -> 0 | AI7: =IF(OR(AE7="",AE7=0),0,AE7*IF(AA7="",0,IF(AA7>1,AA7/100,AA7))) -> 0 | AJ7: =AG7+AH7+AI7 -> 0 | AK7: =IF(OR(AE7="",AE7=0),0,AE7-AJ7) -> 0 | AL7: =IF(AD7="","",AD7-AK7) | AM7: =IF(C7="","","Waiting for payment") | AP7: =IF(OR(C7="",I7="",K7=""),"",IF(K7="Monthly",EDATE(C7,ROUND(I7*SETTINGS!$I$8,0)),WORKDAY(C7,ROUND(I7*SETTINGS!$I$8,0)))) | AQ7: =IF(C7="","",IF(AND(AP7<>"",TODAY()>=AP7),"Refi Ready",IF(TODAY()-C7>=SETTINGS!$I$11,"Prospecting","Performing"))) | AR7: =IF(OR(C7="",I7="",K7=""),"",IF(K7="Monthly",EDATE(C7,I7),WORKDAY(C7,I7))) | AT7: =IF(C7="","",IF(AM7="Clawed Back","CLAWED",IF(TODAY()<=C7+SETTINGS!$I$2,"⚠ AT RISK","SAFE"))) | AW7: =AW6+IF(AND(C7<>"",AO7<>"",OR('REP COMMISSION'!$B$3="",T7='REP COMMISSION'!$B$3,W7='REP COMMISSION'!$B$3,Z7='REP COMMISSION'!$B$3)),1,0) -> 0 | AX7: =AX6+IF(AND(C7<>"",OR(F7="LOC - INITIAL",F7="CONSOLIDATION - UPFRONT COMM",F7="REVERSE - TOTAL FUNDING")),1,0) -> 0
A8: =IF(C8<>"","F"&COUNT($C$4:C8),"") | B8: =IF(OR(F8="LOC - INITIAL",F8="CONSOLIDATION - UPFRONT COMM",F8="REVERSE - TOTAL FUNDING"),A8,"") | J8: =IF(AND(G8<>"",H8<>""),G8*H8,"") | N8: =IF(OR(G8="",M8=""),0,IF(M8>100,M8,G8*IF(M8>1,M8/100,M8))) -> 0 | O8: =IF(G8="","",G8*IF(L8="",0,IF(L8>1,L8/100,L8))+N8) | Q8: =IF(P8="","",IFERROR(VLOOKUP(P8,PARTNERS!$A$2:$B$30,2,0),"")) | R8: =IF(O8="","",IF(OR(P8="",Q8=""),0,(O8-N8)*IF(Q8>1,Q8/100,Q8))) | S8: =IF(O8="","",O8-R8) | U8: =IF(T8="","",IFERROR(VLOOKUP(T8,REPS!$A$2:$D$40,2,0),"")) | V8: =IF(O8="","",IF(U8="",0,O8*IF(U8>1,U8/100,U8))) | X8: =IF(W8="","",IFERROR(VLOOKUP(W8,REPS!$A$2:$D$40,3,0),"")) | Y8: =IF(O8="","",IF(X8="",0,O8*IF(X8>1,X8/100,X8))) | AA8: =IF(Z8="","",IFERROR(VLOOKUP(Z8,REPS!$A$2:$D$40,4,0),"")) | AB8: =IF(O8="","",IF(AA8="",0,O8*IF(AA8>1,AA8/100,AA8))) | AC8: =IF(O8="","",V8+Y8+AB8) | AD8: =IF(O8="","",O8-R8-AC8) | AG8: =IF(OR(AE8="",AE8=0),0,AE8*IF(U8="",0,IF(U8>1,U8/100,U8))) -> 0 | AH8: =IF(OR(AE8="",AE8=0),0,AE8*IF(X8="",0,IF(X8>1,X8/100,X8))) -> 0 | AI8: =IF(OR(AE8="",AE8=0),0,AE8*IF(AA8="",0,IF(AA8>1,AA8/100,AA8))) -> 0 | AJ8: =AG8+AH8+AI8 -> 0 | AK8: =IF(OR(AE8="",AE8=0),0,AE8-AJ8) -> 0 | AL8: =IF(AD8="","",AD8-AK8) | AM8: =IF(C8="","","Waiting for payment") | AP8: =IF(OR(C8="",I8="",K8=""),"",IF(K8="Monthly",EDATE(C8,ROUND(I8*SETTINGS!$I$8,0)),WORKDAY(C8,ROUND(I8*SETTINGS!$I$8,0)))) | AQ8: =IF(C8="","",IF(AND(AP8<>"",TODAY()>=AP8),"Refi Ready",IF(TODAY()-C8>=SETTINGS!$I$11,"Prospecting","Performing"))) | AR8: =IF(OR(C8="",I8="",K8=""),"",IF(K8="Monthly",EDATE(C8,I8),WORKDAY(C8,I8))) | AT8: =IF(C8="","",IF(AM8="Clawed Back","CLAWED",IF(TODAY()<=C8+SETTINGS!$I$2,"⚠ AT RISK","SAFE"))) | AW8: =AW7+IF(AND(C8<>"",AO8<>"",OR('REP COMMISSION'!$B$3="",T8='REP COMMISSION'!$B$3,W8='REP COMMISSION'!$B$3,Z8='REP COMMISSION'!$B$3)),1,0) -> 0 | AX8: =AX7+IF(AND(C8<>"",OR(F8="LOC - INITIAL",F8="CONSOLIDATION - UPFRONT COMM",F8="REVERSE - TOTAL FUNDING")),1,0) -> 0
A9: =IF(C9<>"","F"&COUNT($C$4:C9),"") | B9: =IF(OR(F9="LOC - INITIAL",F9="CONSOLIDATION - UPFRONT COMM",F9="REVERSE - TOTAL FUNDING"),A9,"") | J9: =IF(AND(G9<>"",H9<>""),G9*H9,"") | N9: =IF(OR(G9="",M9=""),0,IF(M9>100,M9,G9*IF(M9>1,M9/100,M9))) -> 0 | O9: =IF(G9="","",G9*IF(L9="",0,IF(L9>1,L9/100,L9))+N9) | Q9: =IF(P9="","",IFERROR(VLOOKUP(P9,PARTNERS!$A$2:$B$30,2,0),"")) | R9: =IF(O9="","",IF(OR(P9="",Q9=""),0,(O9-N9)*IF(Q9>1,Q9/100,Q9))) | S9: =IF(O9="","",O9-R9) | U9: =IF(T9="","",IFERROR(VLOOKUP(T9,REPS!$A$2:$D$40,2,0),"")) | V9: =IF(O9="","",IF(U9="",0,O9*IF(U9>1,U9/100,U9))) | X9: =IF(W9="","",IFERROR(VLOOKUP(W9,REPS!$A$2:$D$40,3,0),"")) | Y9: =IF(O9="","",IF(X9="",0,O9*IF(X9>1,X9/100,X9))) | AA9: =IF(Z9="","",IFERROR(VLOOKUP(Z9,REPS!$A$2:$D$40,4,0),"")) | AB9: =IF(O9="","",IF(AA9="",0,O9*IF(AA9>1,AA9/100,AA9))) | AC9: =IF(O9="","",V9+Y9+AB9) | AD9: =IF(O9="","",O9-R9-AC9) | AG9: =IF(OR(AE9="",AE9=0),0,AE9*IF(U9="",0,IF(U9>1,U9/100,U9))) -> 0 | AH9: =IF(OR(AE9="",AE9=0),0,AE9*IF(X9="",0,IF(X9>1,X9/100,X9))) -> 0 | AI9: =IF(OR(AE9="",AE9=0),0,AE9*IF(AA9="",0,IF(AA9>1,AA9/100,AA9))) -> 0 | AJ9: =AG9+AH9+AI9 -> 0 | AK9: =IF(OR(AE9="",AE9=0),0,AE9-AJ9) -> 0 | AL9: =IF(AD9="","",AD9-AK9) | AM9: =IF(C9="","","Waiting for payment") | AP9: =IF(OR(C9="",I9="",K9=""),"",IF(K9="Monthly",EDATE(C9,ROUND(I9*SETTINGS!$I$8,0)),WORKDAY(C9,ROUND(I9*SETTINGS!$I$8,0)))) | AQ9: =IF(C9="","",IF(AND(AP9<>"",TODAY()>=AP9),"Refi Ready",IF(TODAY()-C9>=SETTINGS!$I$11,"Prospecting","Performing"))) | AR9: =IF(OR(C9="",I9="",K9=""),"",IF(K9="Monthly",EDATE(C9,I9),WORKDAY(C9,I9))) | AT9: =IF(C9="","",IF(AM9="Clawed Back","CLAWED",IF(TODAY()<=C9+SETTINGS!$I$2,"⚠ AT RISK","SAFE"))) | AW9: =AW8+IF(AND(C9<>"",AO9<>"",OR('REP COMMISSION'!$B$3="",T9='REP COMMISSION'!$B$3,W9='REP COMMISSION'!$B$3,Z9='REP COMMISSION'!$B$3)),1,0) -> 0 | AX9: =AX8+IF(AND(C9<>"",OR(F9="LOC - INITIAL",F9="CONSOLIDATION - UPFRONT COMM",F9="REVERSE - TOTAL FUNDING")),1,0) -> 0
A10: =IF(C10<>"","F"&COUNT($C$4:C10),"") | B10: =IF(OR(F10="LOC - INITIAL",F10="CONSOLIDATION - UPFRONT COMM",F10="REVERSE - TOTAL FUNDING"),A10,"") | J10: =IF(AND(G10<>"",H10<>""),G10*H10,"") | N10: =IF(OR(G10="",M10=""),0,IF(M10>100,M10,G10*IF(M10>1,M10/100,M10))) -> 0 | O10: =IF(G10="","",G10*IF(L10="",0,IF(L10>1,L10/100,L10))+N10) | Q10: =IF(P10="","",IFERROR(VLOOKUP(P10,PARTNERS!$A$2:$B$30,2,0),"")) | R10: =IF(O10="","",IF(OR(P10="",Q10=""),0,(O10-N10)*IF(Q10>1,Q10/100,Q10))) | S10: =IF(O10="","",O10-R10) | U10: =IF(T10="","",IFERROR(VLOOKUP(T10,REPS!$A$2:$D$40,2,0),"")) | V10: =IF(O10="","",IF(U10="",0,O10*IF(U10>1,U10/100,U10))) | X10: =IF(W10="","",IFERROR(VLOOKUP(W10,REPS!$A$2:$D$40,3,0),"")) | Y10: =IF(O10="","",IF(X10="",0,O10*IF(X10>1,X10/100,X10))) | AA10: =IF(Z10="","",IFERROR(VLOOKUP(Z10,REPS!$A$2:$D$40,4,0),"")) | AB10: =IF(O10="","",IF(AA10="",0,O10*IF(AA10>1,AA10/100,AA10))) | AC10: =IF(O10="","",V10+Y10+AB10) | AD10: =IF(O10="","",O10-R10-AC10) | AG10: =IF(OR(AE10="",AE10=0),0,AE10*IF(U10="",0,IF(U10>1,U10/100,U10))) -> 0 | AH10: =IF(OR(AE10="",AE10=0),0,AE10*IF(X10="",0,IF(X10>1,X10/100,X10))) -> 0 | AI10: =IF(OR(AE10="",AE10=0),0,AE10*IF(AA10="",0,IF(AA10>1,AA10/100,AA10))) -> 0 | AJ10: =AG10+AH10+AI10 -> 0 | AK10: =IF(OR(AE10="",AE10=0),0,AE10-AJ10) -> 0 | AL10: =IF(AD10="","",AD10-AK10) | AM10: =IF(C10="","","Waiting for payment") | AP10: =IF(OR(C10="",I10="",K10=""),"",IF(K10="Monthly",EDATE(C10,ROUND(I10*SETTINGS!$I$8,0)),WORKDAY(C10,ROUND(I10*SETTINGS!$I$8,0)))) | AQ10: =IF(C10="","",IF(AND(AP10<>"",TODAY()>=AP10),"Refi Ready",IF(TODAY()-C10>=SETTINGS!$I$11,"Prospecting","Performing"))) | AR10: =IF(OR(C10="",I10="",K10=""),"",IF(K10="Monthly",EDATE(C10,I10),WORKDAY(C10,I10))) | AT10: =IF(C10="","",IF(AM10="Clawed Back","CLAWED",IF(TODAY()<=C10+SETTINGS!$I$2,"⚠ AT RISK","SAFE"))) | AW10: =AW9+IF(AND(C10<>"",AO10<>"",OR('REP COMMISSION'!$B$3="",T10='REP COMMISSION'!$B$3,W10='REP COMMISSION'!$B$3,Z10='REP COMMISSION'!$B$3)),1,0) -> 0 | AX10: =AX9+IF(AND(C10<>"",OR(F10="LOC - INITIAL",F10="CONSOLIDATION - UPFRONT COMM",F10="REVERSE - TOTAL FUNDING")),1,0) -> 0
A11: =IF(C11<>"","F"&COUNT($C$4:C11),"") | B11: =IF(OR(F11="LOC - INITIAL",F11="CONSOLIDATION - UPFRONT COMM",F11="REVERSE - TOTAL FUNDING"),A11,"") | J11: =IF(AND(G11<>"",H11<>""),G11*H11,"") | N11: =IF(OR(G11="",M11=""),0,IF(M11>100,M11,G11*IF(M11>1,M11/100,M11))) -> 0 | O11: =IF(G11="","",G11*IF(L11="",0,IF(L11>1,L11/100,L11))+N11) | Q11: =IF(P11="","",IFERROR(VLOOKUP(P11,PARTNERS!$A$2:$B$30,2,0),"")) | R11: =IF(O11="","",IF(OR(P11="",Q11=""),0,(O11-N11)*IF(Q11>1,Q11/100,Q11))) | S11: =IF(O11="","",O11-R11) | U11: =IF(T11="","",IFERROR(VLOOKUP(T11,REPS!$A$2:$D$40,2,0),"")) | V11: =IF(O11="","",IF(U11="",0,O11*IF(U11>1,U11/100,U11))) | X11: =IF(W11="","",IFERROR(VLOOKUP(W11,REPS!$A$2:$D$40,3,0),"")) | Y11: =IF(O11="","",IF(X11="",0,O11*IF(X11>1,X11/100,X11))) | AA11: =IF(Z11="","",IFERROR(VLOOKUP(Z11,REPS!$A$2:$D$40,4,0),"")) | AB11: =IF(O11="","",IF(AA11="",0,O11*IF(AA11>1,AA11/100,AA11))) | AC11: =IF(O11="","",V11+Y11+AB11) | AD11: =IF(O11="","",O11-R11-AC11) | AG11: =IF(OR(AE11="",AE11=0),0,AE11*IF(U11="",0,IF(U11>1,U11/100,U11))) -> 0 | AH11: =IF(OR(AE11="",AE11=0),0,AE11*IF(X11="",0,IF(X11>1,X11/100,X11))) -> 0 | AI11: =IF(OR(AE11="",AE11=0),0,AE11*IF(AA11="",0,IF(AA11>1,AA11/100,AA11))) -> 0 | AJ11: =AG11+AH11+AI11 -> 0 | AK11: =IF(OR(AE11="",AE11=0),0,AE11-AJ11) -> 0 | AL11: =IF(AD11="","",AD11-AK11) | AM11: =IF(C11="","","Waiting for payment") | AP11: =IF(OR(C11="",I11="",K11=""),"",IF(K11="Monthly",EDATE(C11,ROUND(I11*SETTINGS!$I$8,0)),WORKDAY(C11,ROUND(I11*SETTINGS!$I$8,0)))) | AQ11: =IF(C11="","",IF(AND(AP11<>"",TODAY()>=AP11),"Refi Ready",IF(TODAY()-C11>=SETTINGS!$I$11,"Prospecting","Performing"))) | AR11: =IF(OR(C11="",I11="",K11=""),"",IF(K11="Monthly",EDATE(C11,I11),WORKDAY(C11,I11))) | AT11: =IF(C11="","",IF(AM11="Clawed Back","CLAWED",IF(TODAY()<=C11+SETTINGS!$I$2,"⚠ AT RISK","SAFE"))) | AW11: =AW10+IF(AND(C11<>"",AO11<>"",OR('REP COMMISSION'!$B$3="",T11='REP COMMISSION'!$B$3,W11='REP COMMISSION'!$B$3,Z11='REP COMMISSION'!$B$3)),1,0) -> 0 | AX11: =AX10+IF(AND(C11<>"",OR(F11="LOC - INITIAL",F11="CONSOLIDATION - UPFRONT COMM",F11="REVERSE - TOTAL FUNDING")),1,0) -> 0
A12: =IF(C12<>"","F"&COUNT($C$4:C12),"") | B12: =IF(OR(F12="LOC - INITIAL",F12="CONSOLIDATION - UPFRONT COMM",F12="REVERSE - TOTAL FUNDING"),A12,"") | J12: =IF(AND(G12<>"",H12<>""),G12*H12,"") | N12: =IF(OR(G12="",M12=""),0,IF(M12>100,M12,G12*IF(M12>1,M12/100,M12))) -> 0 | O12: =IF(G12="","",G12*IF(L12="",0,IF(L12>1,L12/100,L12))+N12) | Q12: =IF(P12="","",IFERROR(VLOOKUP(P12,PARTNERS!$A$2:$B$30,2,0),"")) | R12: =IF(O12="","",IF(OR(P12="",Q12=""),0,(O12-N12)*IF(Q12>1,Q12/100,Q12))) | S12: =IF(O12="","",O12-R12) | U12: =IF(T12="","",IFERROR(VLOOKUP(T12,REPS!$A$2:$D$40,2,0),"")) | V12: =IF(O12="","",IF(U12="",0,O12*IF(U12>1,U12/100,U12))) | X12: =IF(W12="","",IFERROR(VLOOKUP(W12,REPS!$A$2:$D$40,3,0),"")) | Y12: =IF(O12="","",IF(X12="",0,O12*IF(X12>1,X12/100,X12))) | AA12: =IF(Z12="","",IFERROR(VLOOKUP(Z12,REPS!$A$2:$D$40,4,0),"")) | AB12: =IF(O12="","",IF(AA12="",0,O12*IF(AA12>1,AA12/100,AA12))) | AC12: =IF(O12="","",V12+Y12+AB12) | AD12: =IF(O12="","",O12-R12-AC12) | AG12: =IF(OR(AE12="",AE12=0),0,AE12*IF(U12="",0,IF(U12>1,U12/100,U12))) -> 0 | AH12: =IF(OR(AE12="",AE12=0),0,AE12*IF(X12="",0,IF(X12>1,X12/100,X12))) -> 0 | AI12: =IF(OR(AE12="",AE12=0),0,AE12*IF(AA12="",0,IF(AA12>1,AA12/100,AA12))) -> 0 | AJ12: =AG12+AH12+AI12 -> 0 | AK12: =IF(OR(AE12="",AE12=0),0,AE12-AJ12) -> 0 | AL12: =IF(AD12="","",AD12-AK12) | AM12: =IF(C12="","","Waiting for payment") | AP12: =IF(OR(C12="",I12="",K12=""),"",IF(K12="Monthly",EDATE(C12,ROUND(I12*SETTINGS!$I$8,0)),WORKDAY(C12,ROUND(I12*SETTINGS!$I$8,0)))) | AQ12: =IF(C12="","",IF(AND(AP12<>"",TODAY()>=AP12),"Refi Ready",IF(TODAY()-C12>=SETTINGS!$I$11,"Prospecting","Performing"))) | AR12: =IF(OR(C12="",I12="",K12=""),"",IF(K12="Monthly",EDATE(C12,I12),WORKDAY(C12,I12))) | AT12: =IF(C12="","",IF(AM12="Clawed Back","CLAWED",IF(TODAY()<=C12+SETTINGS!$I$2,"⚠ AT RISK","SAFE"))) | AW12: =AW11+IF(AND(C12<>"",AO12<>"",OR('REP COMMISSION'!$B$3="",T12='REP COMMISSION'!$B$3,W12='REP COMMISSION'!$B$3,Z12='REP COMMISSION'!$B$3)),1,0) -> 0 | AX12: =AX11+IF(AND(C12<>"",OR(F12="LOC - INITIAL",F12="CONSOLIDATION - UPFRONT COMM",F12="REVERSE - TOTAL FUNDING")),1,0) -> 0
A13: =IF(C13<>"","F"&COUNT($C$4:C13),"") | B13: =IF(OR(F13="LOC - INITIAL",F13="CONSOLIDATION - UPFRONT COMM",F13="REVERSE - TOTAL FUNDING"),A13,"") | J13: =IF(AND(G13<>"",H13<>""),G13*H13,"") | N13: =IF(OR(G13="",M13=""),0,IF(M13>100,M13,G13*IF(M13>1,M13/100,M13))) -> 0 | O13: =IF(G13="","",G13*IF(L13="",0,IF(L13>1,L13/100,L13))+N13) | Q13: =IF(P13="","",IFERROR(VLOOKUP(P13,PARTNERS!$A$2:$B$30,2,0),"")) | R13: =IF(O13="","",IF(OR(P13="",Q13=""),0,(O13-N13)*IF(Q13>1,Q13/100,Q13))) | S13: =IF(O13="","",O13-R13) | U13: =IF(T13="","",IFERROR(VLOOKUP(T13,REPS!$A$2:$D$40,2,0),"")) | V13: =IF(O13="","",IF(U13="",0,O13*IF(U13>1,U13/100,U13))) | X13: =IF(W13="","",IFERROR(VLOOKUP(W13,REPS!$A$2:$D$40,3,0),"")) | Y13: =IF(O13="","",IF(X13="",0,O13*IF(X13>1,X13/100,X13))) | AA13: =IF(Z13="","",IFERROR(VLOOKUP(Z13,REPS!$A$2:$D$40,4,0),"")) | AB13: =IF(O13="","",IF(AA13="",0,O13*IF(AA13>1,AA13/100,AA13))) | AC13: =IF(O13="","",V13+Y13+AB13) | AD13: =IF(O13="","",O13-R13-AC13) | AG13: =IF(OR(AE13="",AE13=0),0,AE13*IF(U13="",0,IF(U13>1,U13/100,U13))) -> 0 | AH13: =IF(OR(AE13="",AE13=0),0,AE13*IF(X13="",0,IF(X13>1,X13/100,X13))) -> 0 | AI13: =IF(OR(AE13="",AE13=0),0,AE13*IF(AA13="",0,IF(AA13>1,AA13/100,AA13))) -> 0 | AJ13: =AG13+AH13+AI13 -> 0 | AK13: =IF(OR(AE13="",AE13=0),0,AE13-AJ13) -> 0 | AL13: =IF(AD13="","",AD13-AK13) | AM13: =IF(C13="","","Waiting for payment") | AP13: =IF(OR(C13="",I13="",K13=""),"",IF(K13="Monthly",EDATE(C13,ROUND(I13*SETTINGS!$I$8,0)),WORKDAY(C13,ROUND(I13*SETTINGS!$I$8,0)))) | AQ13: =IF(C13="","",IF(AND(AP13<>"",TODAY()>=AP13),"Refi Ready",IF(TODAY()-C13>=SETTINGS!$I$11,"Prospecting","Performing"))) | AR13: =IF(OR(C13="",I13="",K13=""),"",IF(K13="Monthly",EDATE(C13,I13),WORKDAY(C13,I13))) | AT13: =IF(C13="","",IF(AM13="Clawed Back","CLAWED",IF(TODAY()<=C13+SETTINGS!$I$2,"⚠ AT RISK","SAFE"))) | AW13: =AW12+IF(AND(C13<>"",AO13<>"",OR('REP COMMISSION'!$B$3="",T13='REP COMMISSION'!$B$3,W13='REP COMMISSION'!$B$3,Z13='REP COMMISSION'!$B$3)),1,0) -> 0 | AX13: =AX12+IF(AND(C13<>"",OR(F13="LOC - INITIAL",F13="CONSOLIDATION - UPFRONT COMM",F13="REVERSE - TOTAL FUNDING")),1,0) -> 0
A14: =IF(C14<>"","F"&COUNT($C$4:C14),"") | B14: =IF(OR(F14="LOC - INITIAL",F14="CONSOLIDATION - UPFRONT COMM",F14="REVERSE - TOTAL FUNDING"),A14,"") | J14: =IF(AND(G14<>"",H14<>""),G14*H14,"") | N14: =IF(OR(G14="",M14=""),0,IF(M14>100,M14,G14*IF(M14>1,M14/100,M14))) -> 0 | O14: =IF(G14="","",G14*IF(L14="",0,IF(L14>1,L14/100,L14))+N14) | Q14: =IF(P14="","",IFERROR(VLOOKUP(P14,PARTNERS!$A$2:$B$30,2,0),"")) | R14: =IF(O14="","",IF(OR(P14="",Q14=""),0,(O14-N14)*IF(Q14>1,Q14/100,Q14))) | S14: =IF(O14="","",O14-R14) | U14: =IF(T14="","",IFERROR(VLOOKUP(T14,REPS!$A$2:$D$40,2,0),"")) | V14: =IF(O14="","",IF(U14="",0,O14*IF(U14>1,U14/100,U14))) | X14: =IF(W14="","",IFERROR(VLOOKUP(W14,REPS!$A$2:$D$40,3,0),"")) | Y14: =IF(O14="","",IF(X14="",0,O14*IF(X14>1,X14/100,X14))) | AA14: =IF(Z14="","",IFERROR(VLOOKUP(Z14,REPS!$A$2:$D$40,4,0),"")) | AB14: =IF(O14="","",IF(AA14="",0,O14*IF(AA14>1,AA14/100,AA14))) | AC14: =IF(O14="","",V14+Y14+AB14) | AD14: =IF(O14="","",O14-R14-AC14) | AG14: =IF(OR(AE14="",AE14=0),0,AE14*IF(U14="",0,IF(U14>1,U14/100,U14))) -> 0 | AH14: =IF(OR(AE14="",AE14=0),0,AE14*IF(X14="",0,IF(X14>1,X14/100,X14))) -> 0 | AI14: =IF(OR(AE14="",AE14=0),0,AE14*IF(AA14="",0,IF(AA14>1,AA14/100,AA14))) -> 0 | AJ14: =AG14+AH14+AI14 -> 0 | AK14: =IF(OR(AE14="",AE14=0),0,AE14-AJ14) -> 0 | AL14: =IF(AD14="","",AD14-AK14) | AM14: =IF(C14="","","Waiting for payment") | AP14: =IF(OR(C14="",I14="",K14=""),"",IF(K14="Monthly",EDATE(C14,ROUND(I14*SETTINGS!$I$8,0)),WORKDAY(C14,ROUND(I14*SETTINGS!$I$8,0)))) | AQ14: =IF(C14="","",IF(AND(AP14<>"",TODAY()>=AP14),"Refi Ready",IF(TODAY()-C14>=SETTINGS!$I$11,"Prospecting","Performing"))) | AR14: =IF(OR(C14="",I14="",K14=""),"",IF(K14="Monthly",EDATE(C14,I14),WORKDAY(C14,I14))) | AT14: =IF(C14="","",IF(AM14="Clawed Back","CLAWED",IF(TODAY()<=C14+SETTINGS!$I$2,"⚠ AT RISK","SAFE"))) | AW14: =AW13+IF(AND(C14<>"",AO14<>"",OR('REP COMMISSION'!$B$3="",T14='REP COMMISSION'!$B$3,W14='REP COMMISSION'!$B$3,Z14='REP COMMISSION'!$B$3)),1,0) -> 0 | AX14: =AX13+IF(AND(C14<>"",OR(F14="LOC - INITIAL",F14="CONSOLIDATION - UPFRONT COMM",F14="REVERSE - TOTAL FUNDING")),1,0) -> 0
A15: =IF(C15<>"","F"&COUNT($C$4:C15),"") | B15: =IF(OR(F15="LOC - INITIAL",F15="CONSOLIDATION - UPFRONT COMM",F15="REVERSE - TOTAL FUNDING"),A15,"") | J15: =IF(AND(G15<>"",H15<>""),G15*H15,"") | N15: =IF(OR(G15="",M15=""),0,IF(M15>100,M15,G15*IF(M15>1,M15/100,M15))) -> 0 | O15: =IF(G15="","",G15*IF(L15="",0,IF(L15>1,L15/100,L15))+N15) | Q15: =IF(P15="","",IFERROR(VLOOKUP(P15,PARTNERS!$A$2:$B$30,2,0),"")) | R15: =IF(O15="","",IF(OR(P15="",Q15=""),0,(O15-N15)*IF(Q15>1,Q15/100,Q15))) | S15: =IF(O15="","",O15-R15) | U15: =IF(T15="","",IFERROR(VLOOKUP(T15,REPS!$A$2:$D$40,2,0),"")) | V15: =IF(O15="","",IF(U15="",0,O15*IF(U15>1,U15/100,U15))) | X15: =IF(W15="","",IFERROR(VLOOKUP(W15,REPS!$A$2:$D$40,3,0),"")) | Y15: =IF(O15="","",IF(X15="",0,O15*IF(X15>1,X15/100,X15))) | AA15: =IF(Z15="","",IFERROR(VLOOKUP(Z15,REPS!$A$2:$D$40,4,0),"")) | AB15: =IF(O15="","",IF(AA15="",0,O15*IF(AA15>1,AA15/100,AA15))) | AC15: =IF(O15="","",V15+Y15+AB15) | AD15: =IF(O15="","",O15-R15-AC15) | AG15: =IF(OR(AE15="",AE15=0),0,AE15*IF(U15="",0,IF(U15>1,U15/100,U15))) -> 0 | AH15: =IF(OR(AE15="",AE15=0),0,AE15*IF(X15="",0,IF(X15>1,X15/100,X15))) -> 0 | AI15: =IF(OR(AE15="",AE15=0),0,AE15*IF(AA15="",0,IF(AA15>1,AA15/100,AA15))) -> 0 | AJ15: =AG15+AH15+AI15 -> 0 | AK15: =IF(OR(AE15="",AE15=0),0,AE15-AJ15) -> 0 | AL15: =IF(AD15="","",AD15-AK15) | AM15: =IF(C15="","","Waiting for payment") | AP15: =IF(OR(C15="",I15="",K15=""),"",IF(K15="Monthly",EDATE(C15,ROUND(I15*SETTINGS!$I$8,0)),WORKDAY(C15,ROUND(I15*SETTINGS!$I$8,0)))) | AQ15: =IF(C15="","",IF(AND(AP15<>"",TODAY()>=AP15),"Refi Ready",IF(TODAY()-C15>=SETTINGS!$I$11,"Prospecting","Performing"))) | AR15: =IF(OR(C15="",I15="",K15=""),"",IF(K15="Monthly",EDATE(C15,I15),WORKDAY(C15,I15))) | AT15: =IF(C15="","",IF(AM15="Clawed Back","CLAWED",IF(TODAY()<=C15+SETTINGS!$I$2,"⚠ AT RISK","SAFE"))) | AW15: =AW14+IF(AND(C15<>"",AO15<>"",OR('REP COMMISSION'!$B$3="",T15='REP COMMISSION'!$B$3,W15='REP COMMISSION'!$B$3,Z15='REP COMMISSION'!$B$3)),1,0) -> 0 | AX15: =AX14+IF(AND(C15<>"",OR(F15="LOC - INITIAL",F15="CONSOLIDATION - UPFRONT COMM",F15="REVERSE - TOTAL FUNDING")),1,0) -> 0
... A103: =IF(C103<>"","F"&COUNT($C$4:C103),"") | B103: =IF(OR(F103="LOC - INITIAL",F103="CONSOLIDATION - UPFRONT COMM",F103="REVERSE - TOTAL FUNDING"),A103,"") | J103: =IF(AND(G103<>"",H103<>""),G103*H103,"") | N103: =IF(OR(G103="",M103=""),0,IF(M103>100,M103,G103*IF(M103>1,M103/100,M103))) -> 0 | O103: =IF(G103="","",G103*IF(L103="",0,IF(L103>1,L103/100,L103))+N103) | Q103: =IF(P103="","",IFERROR(VLOOKUP(P103,PARTNERS!$A$2:$B$30,2,0),"")) | R103: =IF(O103="","",IF(OR(P103="",Q103=""),0,(O103-N103)*IF(Q103>1,Q103/100,Q103))) | S103: =IF(O103="","",O103-R103) | U103: =IF(T103="","",IFERROR(VLOOKUP(T103,REPS!$A$2:$D$40,2,0),"")) | V103: =IF(O103="","",IF(U103="",0,O103*IF(U103>1,U103/100,U103))) | X103: =IF(W103="","",IFERROR(VLOOKUP(W103,REPS!$A$2:$D$40,3,0),"")) | Y103: =IF(O103="","",IF(X103="",0,O103*IF(X103>1,X103/100,X103))) | AA103: =IF(Z103="","",IFERROR(VLOOKUP(Z103,REPS!$A$2:$D$40,4,0),"")) | AB103: =IF(O103="","",IF(AA103="",0,O103*IF(AA103>1,AA103/100,AA103))) | AC103: =IF(O103="","",V103+Y103+AB103) | AD103: =IF(O103="","",O103-R103-AC103) | AG103: =IF(OR(AE103="",AE103=0),0,AE103*IF(U103="",0,IF(U103>1,U103/100,U103))) -> 0 | AH103: =IF(OR(AE103="",AE103=0),0,AE103*IF(X103="",0,IF(X103>1,X103/100,X103))) -> 0 | AI103: =IF(OR(AE103="",AE103=0),0,AE103*IF(AA103="",0,IF(AA103>1,AA103/100,AA103))) -> 0 | AJ103: =AG103+AH103+AI103 -> 0 | AK103: =IF(OR(AE103="",AE103=0),0,AE103-AJ103) -> 0 | AL103: =IF(AD103="","",AD103-AK103) | AM103: =IF(C103="","","Waiting for payment") | AP103: =IF(OR(C103="",I103="",K103=""),"",IF(K103="Monthly",EDATE(C103,ROUND(I103*SETTINGS!$I$8,0)),WORKDAY(C103,ROUND(I103*SETTINGS!$I$8,0)))) | AQ103: =IF(C103="","",IF(AND(AP103<>"",TODAY()>=AP103),"Refi Ready",IF(TODAY()-C103>=SETTINGS!$I$11,"Prospecting","Performing"))) | AR103: =IF(OR(C103="",I103="",K103=""),"",IF(K103="Monthly",EDATE(C103,I103),WORKDAY(C103,I103))) | AT103: =IF(C103="","",IF(AM103="Clawed Back","CLAWED",IF(TODAY()<=C103+SETTINGS!$I$2,"⚠ AT RISK","SAFE"))) | AW103: =AW102+IF(AND(C103<>"",AO103<>"",OR('REP COMMISSION'!$B$3="",T103='REP COMMISSION'!$B$3,W103='REP COMMISSION'!$B$3,Z103='REP COMMISSION'!$B$3)),1,0) -> 0 | AX103: =AX102+IF(AND(C103<>"",OR(F103="LOC - INITIAL",F103="CONSOLIDATION - UPFRONT COMM",F103="REVERSE - TOTAL FUNDING")),1,0) -> 0
A104: APRIL TOTAL | D104: =COUNT(C4:C103)&" units" -> 0 units | G104: =SUM(G4:G103) -> 0 | N104: =SUM(N4:N103) -> 0 | O104: =SUM(O4:O103) -> 0 | R104: =SUM(R4:R103) -> 0 | S104: =SUM(S4:S103) -> 0 | AC104: =SUM(AC4:AC103) -> 0 | AD104: =SUM(AD4:AD103) -> 0 | AE104: =SUM(AE4:AE103) -> 0 | AJ104: =SUM(AJ4:AJ103) -> 0 | AK104: =SUM(AK4:AK103) -> 0 | AL104: =SUM(AL4:AL103) -> 0 | AW104: =AW103 -> 0 | AX104: =AX103 -> 0
A105: ▼ MAY 2026 | AW105: =AW104 -> 0 | AX105: =AX104 -> 0
A106: =IF(C106<>"","F"&COUNT($C$4:C106),"") | B106: =IF(OR(F106="LOC - INITIAL",F106="CONSOLIDATION - UPFRONT COMM",F106="REVERSE - TOTAL FUNDING"),A106,"") | J106: =IF(AND(G106<>"",H106<>""),G106*H106,"") | N106: =IF(OR(G106="",M106=""),0,IF(M106>100,M106,G106*IF(M106>1,M106/100,M106))) -> 0 | O106: =IF(G106="","",G106*IF(L106="",0,IF(L106>1,L106/100,L106))+N106) | Q106: =IF(P106="","",IFERROR(VLOOKUP(P106,PARTNERS!$A$2:$B$30,2,0),"")) | R106: =IF(O106="","",IF(OR(P106="",Q106=""),0,(O106-N106)*IF(Q106>1,Q106/100,Q106))) | S106: =IF(O106="","",O106-R106) | U106: =IF(T106="","",IFERROR(VLOOKUP(T106,REPS!$A$2:$D$40,2,0),"")) | V106: =IF(O106="","",IF(U106="",0,O106*IF(U106>1,U106/100,U106))) | X106: =IF(W106="","",IFERROR(VLOOKUP(W106,REPS!$A$2:$D$40,3,0),"")) | Y106: =IF(O106="","",IF(X106="",0,O106*IF(X106>1,X106/100,X106))) | AA106: =IF(Z106="","",IFERROR(VLOOKUP(Z106,REPS!$A$2:$D$40,4,0),"")) | AB106: =IF(O106="","",IF(AA106="",0,O106*IF(AA106>1,AA106/100,AA106))) | AC106: =IF(O106="","",V106+Y106+AB106) | AD106: =IF(O106="","",O106-R106-AC106) | AG106: =IF(OR(AE106="",AE106=0),0,AE106*IF(U106="",0,IF(U106>1,U106/100,U106))) -> 0 | AH106: =IF(OR(AE106="",AE106=0),0,AE106*IF(X106="",0,IF(X106>1,X106/100,X106))) -> 0 | AI106: =IF(OR(AE106="",AE106=0),0,AE106*IF(AA106="",0,IF(AA106>1,AA106/100,AA106))) -> 0 | AJ106: =AG106+AH106+AI106 -> 0 | AK106: =IF(OR(AE106="",AE106=0),0,AE106-AJ106) -> 0 | AL106: =IF(AD106="","",AD106-AK106) | AM106: =IF(C106="","","Waiting for payment") | AP106: =IF(OR(C106="",I106="",K106=""),"",IF(K106="Monthly",EDATE(C106,ROUND(I106*SETTINGS!$I$8,0)),WORKDAY(C106,ROUND(I106*SETTINGS!$I$8,0)))) | AQ106: =IF(C106="","",IF(AND(AP106<>"",TODAY()>=AP106),"Refi Ready",IF(TODAY()-C106>=SETTINGS!$I$11,"Prospecting","Performing"))) | AR106: =IF(OR(C106="",I106="",K106=""),"",IF(K106="Monthly",EDATE(C106,I106),WORKDAY(C106,I106))) | AT106: =IF(C106="","",IF(AM106="Clawed Back","CLAWED",IF(TODAY()<=C106+SETTINGS!$I$2,"⚠ AT RISK","SAFE"))) | AW106: =AW105+IF(AND(C106<>"",AO106<>"",OR('REP COMMISSION'!$B$3="",T106='REP COMMISSION'!$B$3,W106='REP COMMISSION'!$B$3,Z106='REP COMMISSION'!$B$3)),1,0) -> 0 | AX106: =AX105+IF(AND(C106<>"",OR(F106="LOC - INITIAL",F106="CONSOLIDATION - UPFRONT COMM",F106="REVERSE - TOTAL FUNDING")),1,0) -> 0
A107: =IF(C107<>"","F"&COUNT($C$4:C107),"") | B107: =IF(OR(F107="LOC - INITIAL",F107="CONSOLIDATION - UPFRONT COMM",F107="REVERSE - TOTAL FUNDING"),A107,"") | J107: =IF(AND(G107<>"",H107<>""),G107*H107,"") | N107: =IF(OR(G107="",M107=""),0,IF(M107>100,M107,G107*IF(M107>1,M107/100,M107))) -> 0 | O107: =IF(G107="","",G107*IF(L107="",0,IF(L107>1,L107/100,L107))+N107) | Q107: =IF(P107="","",IFERROR(VLOOKUP(P107,PARTNERS!$A$2:$B$30,2,0),"")) | R107: =IF(O107="","",IF(OR(P107="",Q107=""),0,(O107-N107)*IF(Q107>1,Q107/100,Q107))) | S107: =IF(O107="","",O107-R107) | U107: =IF(T107="","",IFERROR(VLOOKUP(T107,REPS!$A$2:$D$40,2,0),"")) | V107: =IF(O107="","",IF(U107="",0,O107*IF(U107>1,U107/100,U107))) | X107: =IF(W107="","",IFERROR(VLOOKUP(W107,REPS!$A$2:$D$40,3,0),"")) | Y107: =IF(O107="","",IF(X107="",0,O107*IF(X107>1,X107/100,X107))) | AA107: =IF(Z107="","",IFERROR(VLOOKUP(Z107,REPS!$A$2:$D$40,4,0),"")) | AB107: =IF(O107="","",IF(AA107="",0,O107*IF(AA107>1,AA107/100,AA107))) | AC107: =IF(O107="","",V107+Y107+AB107) | AD107: =IF(O107="","",O107-R107-AC107) | AG107: =IF(OR(AE107="",AE107=0),0,AE107*IF(U107="",0,IF(U107>1,U107/100,U107))) -> 0 | AH107: =IF(OR(AE107="",AE107=0),0,AE107*IF(X107="",0,IF(X107>1,X107/100,X107))) -> 0 | AI107: =IF(OR(AE107="",AE107=0),0,AE107*IF(AA107="",0,IF(AA107>1,AA107/100,AA107))) -> 0 | AJ107: =AG107+AH107+AI107 -> 0 | AK107: =IF(OR(AE107="",AE107=0),0,AE107-AJ107) -> 0 | AL107: =IF(AD107="","",AD107-AK107) | AM107: =IF(C107="","","Waiting for payment") | AP107: =IF(OR(C107="",I107="",K107=""),"",IF(K107="Monthly",EDATE(C107,ROUND(I107*SETTINGS!$I$8,0)),WORKDAY(C107,ROUND(I107*SETTINGS!$I$8,0)))) | AQ107: =IF(C107="","",IF(AND(AP107<>"",TODAY()>=AP107),"Refi Ready",IF(TODAY()-C107>=SETTINGS!$I$11,"Prospecting","Performing"))) | AR107: =IF(OR(C107="",I107="",K107=""),"",IF(K107="Monthly",EDATE(C107,I107),WORKDAY(C107,I107))) | AT107: =IF(C107="","",IF(AM107="Clawed Back","CLAWED",IF(TODAY()<=C107+SETTINGS!$I$2,"⚠ AT RISK","SAFE"))) | AW107: =AW106+IF(AND(C107<>"",AO107<>"",OR('REP COMMISSION'!$B$3="",T107='REP COMMISSION'!$B$3,W107='REP COMMISSION'!$B$3,Z107='REP COMMISSION'!$B$3)),1,0) -> 0 | AX107: =AX106+IF(AND(C107<>"",OR(F107="LOC - INITIAL",F107="CONSOLIDATION - UPFRONT COMM",F107="REVERSE - TOTAL FUNDING")),1,0) -> 0
A108: =IF(C108<>"","F"&COUNT($C$4:C108),"") | B108: =IF(OR(F108="LOC - INITIAL",F108="CONSOLIDATION - UPFRONT COMM",F108="REVERSE - TOTAL FUNDING"),A108,"") | J108: =IF(AND(G108<>"",H108<>""),G108*H108,"") | N108: =IF(OR(G108="",M108=""),0,IF(M108>100,M108,G108*IF(M108>1,M108/100,M108))) -> 0 | O108: =IF(G108="","",G108*IF(L108="",0,IF(L108>1,L108/100,L108))+N108) | Q108: =IF(P108="","",IFERROR(VLOOKUP(P108,PARTNERS!$A$2:$B$30,2,0),"")) | R108: =IF(O108="","",IF(OR(P108="",Q108=""),0,(O108-N108)*IF(Q108>1,Q108/100,Q108))) | S108: =IF(O108="","",O108-R108) | U108: =IF(T108="","",IFERROR(VLOOKUP(T108,REPS!$A$2:$D$40,2,0),"")) | V108: =IF(O108="","",IF(U108="",0,O108*IF(U108>1,U108/100,U108))) | X108: =IF(W108="","",IFERROR(VLOOKUP(W108,REPS!$A$2:$D$40,3,0),"")) | Y108: =IF(O108="","",IF(X108="",0,O108*IF(X108>1,X108/100,X108))) | AA108: =IF(Z108="","",IFERROR(VLOOKUP(Z108,REPS!$A$2:$D$40,4,0),"")) | AB108: =IF(O108="","",IF(AA108="",0,O108*IF(AA108>1,AA108/100,AA108))) | AC108: =IF(O108="","",V108+Y108+AB108) | AD108: =IF(O108="","",O108-R108-AC108) | AG108: =IF(OR(AE108="",AE108=0),0,AE108*IF(U108="",0,IF(U108>1,U108/100,U108))) -> 0 | AH108: =IF(OR(AE108="",AE108=0),0,AE108*IF(X108="",0,IF(X108>1,X108/100,X108))) -> 0 | AI108: =IF(OR(AE108="",AE108=0),0,AE108*IF(AA108="",0,IF(AA108>1,AA108/100,AA108))) -> 0 | AJ108: =AG108+AH108+AI108 -> 0 | AK108: =IF(OR(AE108="",AE108=0),0,AE108-AJ108) -> 0 | AL108: =IF(AD108="","",AD108-AK108) | AM108: =IF(C108="","","Waiting for payment") | AP108: =IF(OR(C108="",I108="",K108=""),"",IF(K108="Monthly",EDATE(C108,ROUND(I108*SETTINGS!$I$8,0)),WORKDAY(C108,ROUND(I108*SETTINGS!$I$8,0)))) | AQ108: =IF(C108="","",IF(AND(AP108<>"",TODAY()>=AP108),"Refi Ready",IF(TODAY()-C108>=SETTINGS!$I$11,"Prospecting","Performing"))) | AR108: =IF(OR(C108="",I108="",K108=""),"",IF(K108="Monthly",EDATE(C108,I108),WORKDAY(C108,I108))) | AT108: =IF(C108="","",IF(AM108="Clawed Back","CLAWED",IF(TODAY()<=C108+SETTINGS!$I$2,"⚠ AT RISK","SAFE"))) | AW108: =AW107+IF(AND(C108<>"",AO108<>"",OR('REP COMMISSION'!$B$3="",T108='REP COMMISSION'!$B$3,W108='REP COMMISSION'!$B$3,Z108='REP COMMISSION'!$B$3)),1,0) -> 0 | AX108: =AX107+IF(AND(C108<>"",OR(F108="LOC - INITIAL",F108="CONSOLIDATION - UPFRONT COMM",F108="REVERSE - TOTAL FUNDING")),1,0) -> 0
A109: =IF(C109<>"","F"&COUNT($C$4:C109),"") | B109: =IF(OR(F109="LOC - INITIAL",F109="CONSOLIDATION - UPFRONT COMM",F109="REVERSE - TOTAL FUNDING"),A109,"") | J109: =IF(AND(G109<>"",H109<>""),G109*H109,"") | N109: =IF(OR(G109="",M109=""),0,IF(M109>100,M109,G109*IF(M109>1,M109/100,M109))) -> 0 | O109: =IF(G109="","",G109*IF(L109="",0,IF(L109>1,L109/100,L109))+N109) | Q109: =IF(P109="","",IFERROR(VLOOKUP(P109,PARTNERS!$A$2:$B$30,2,0),"")) | R109: =IF(O109="","",IF(OR(P109="",Q109=""),0,(O109-N109)*IF(Q109>1,Q109/100,Q109))) | S109: =IF(O109="","",O109-R109) | U109: =IF(T109="","",IFERROR(VLOOKUP(T109,REPS!$A$2:$D$40,2,0),"")) | V109: =IF(O109="","",IF(U109="",0,O109*IF(U109>1,U109/100,U109))) | X109: =IF(W109="","",IFERROR(VLOOKUP(W109,REPS!$A$2:$D$40,3,0),"")) | Y109: =IF(O109="","",IF(X109="",0,O109*IF(X109>1,X109/100,X109))) | AA109: =IF(Z109="","",IFERROR(VLOOKUP(Z109,REPS!$A$2:$D$40,4,0),"")) | AB109: =IF(O109="","",IF(AA109="",0,O109*IF(AA109>1,AA109/100,AA109))) | AC109: =IF(O109="","",V109+Y109+AB109) | AD109: =IF(O109="","",O109-R109-AC109) | AG109: =IF(OR(AE109="",AE109=0),0,AE109*IF(U109="",0,IF(U109>1,U109/100,U109))) -> 0 | AH109: =IF(OR(AE109="",AE109=0),0,AE109*IF(X109="",0,IF(X109>1,X109/100,X109))) -> 0 | AI109: =IF(OR(AE109="",AE109=0),0,AE109*IF(AA109="",0,IF(AA109>1,AA109/100,AA109))) -> 0 | AJ109: =AG109+AH109+AI109 -> 0 | AK109: =IF(OR(AE109="",AE109=0),0,AE109-AJ109) -> 0 | AL109: =IF(AD109="","",AD109-AK109) | AM109: =IF(C109="","","Waiting for payment") | AP109: =IF(OR(C109="",I109="",K109=""),"",IF(K109="Monthly",EDATE(C109,ROUND(I109*SETTINGS!$I$8,0)),WORKDAY(C109,ROUND(I109*SETTINGS!$I$8,0)))) | AQ109: =IF(C109="","",IF(AND(AP109<>"",TODAY()>=AP109),"Refi Ready",IF(TODAY()-C109>=SETTINGS!$I$11,"Prospecting","Performing"))) | AR109: =IF(OR(C109="",I109="",K109=""),"",IF(K109="Monthly",EDATE(C109,I109),WORKDAY(C109,I109))) | AT109: =IF(C109="","",IF(AM109="Clawed Back","CLAWED",IF(TODAY()<=C109+SETTINGS!$I$2,"⚠ AT RISK","SAFE"))) | AW109: =AW108+IF(AND(C109<>"",AO109<>"",OR('REP COMMISSION'!$B$3="",T109='REP COMMISSION'!$B$3,W109='REP COMMISSION'!$B$3,Z109='REP COMMISSION'!$B$3)),1,0) -> 0 | AX109: =AX108+IF(AND(C109<>"",OR(F109="LOC - INITIAL",F109="CONSOLIDATION - UPFRONT COMM",F109="REVERSE - TOTAL FUNDING")),1,0) -> 0
A110: =IF(C110<>"","F"&COUNT($C$4:C110),"") | B110: =IF(OR(F110="LOC - INITIAL",F110="CONSOLIDATION - UPFRONT COMM",F110="REVERSE - TOTAL FUNDING"),A110,"") | J110: =IF(AND(G110<>"",H110<>""),G110*H110,"") | N110: =IF(OR(G110="",M110=""),0,IF(M110>100,M110,G110*IF(M110>1,M110/100,M110))) -> 0 | O110: =IF(G110="","",G110*IF(L110="",0,IF(L110>1,L110/100,L110))+N110) | Q110: =IF(P110="","",IFERROR(VLOOKUP(P110,PARTNERS!$A$2:$B$30,2,0),"")) | R110: =IF(O110="","",IF(OR(P110="",Q110=""),0,(O110-N110)*IF(Q110>1,Q110/100,Q110))) | S110: =IF(O110="","",O110-R110) | U110: =IF(T110="","",IFERROR(VLOOKUP(T110,REPS!$A$2:$D$40,2,0),"")) | V110: =IF(O110="","",IF(U110="",0,O110*IF(U110>1,U110/100,U110))) | X110: =IF(W110="","",IFERROR(VLOOKUP(W110,REPS!$A$2:$D$40,3,0),"")) | Y110: =IF(O110="","",IF(X110="",0,O110*IF(X110>1,X110/100,X110))) | AA110: =IF(Z110="","",IFERROR(VLOOKUP(Z110,REPS!$A$2:$D$40,4,0),"")) | AB110: =IF(O110="","",IF(AA110="",0,O110*IF(AA110>1,AA110/100,AA110))) | AC110: =IF(O110="","",V110+Y110+AB110) | AD110: =IF(O110="","",O110-R110-AC110) | AG110: =IF(OR(AE110="",AE110=0),0,AE110*IF(U110="",0,IF(U110>1,U110/100,U110))) -> 0 | AH110: =IF(OR(AE110="",AE110=0),0,AE110*IF(X110="",0,IF(X110>1,X110/100,X110))) -> 0 | AI110: =IF(OR(AE110="",AE110=0),0,AE110*IF(AA110="",0,IF(AA110>1,AA110/100,AA110))) -> 0 | AJ110: =AG110+AH110+AI110 -> 0 | AK110: =IF(OR(AE110="",AE110=0),0,AE110-AJ110) -> 0 | AL110: =IF(AD110="","",AD110-AK110) | AM110: =IF(C110="","","Waiting for payment") | AP110: =IF(OR(C110="",I110="",K110=""),"",IF(K110="Monthly",EDATE(C110,ROUND(I110*SETTINGS!$I$8,0)),WORKDAY(C110,ROUND(I110*SETTINGS!$I$8,0)))) | AQ110: =IF(C110="","",IF(AND(AP110<>"",TODAY()>=AP110),"Refi Ready",IF(TODAY()-C110>=SETTINGS!$I$11,"Prospecting","Performing"))) | AR110: =IF(OR(C110="",I110="",K110=""),"",IF(K110="Monthly",EDATE(C110,I110),WORKDAY(C110,I110))) | AT110: =IF(C110="","",IF(AM110="Clawed Back","CLAWED",IF(TODAY()<=C110+SETTINGS!$I$2,"⚠ AT RISK","SAFE"))) | AW110: =AW109+IF(AND(C110<>"",AO110<>"",OR('REP COMMISSION'!$B$3="",T110='REP COMMISSION'!$B$3,W110='REP COMMISSION'!$B$3,Z110='REP COMMISSION'!$B$3)),1,0) -> 0 | AX110: =AX109+IF(AND(C110<>"",OR(F110="LOC - INITIAL",F110="CONSOLIDATION - UPFRONT COMM",F110="REVERSE - TOTAL FUNDING")),1,0) -> 0
A111: =IF(C111<>"","F"&COUNT($C$4:C111),"") | B111: =IF(OR(F111="LOC - INITIAL",F111="CONSOLIDATION - UPFRONT COMM",F111="REVERSE - TOTAL FUNDING"),A111,"") | J111: =IF(AND(G111<>"",H111<>""),G111*H111,"") | N111: =IF(OR(G111="",M111=""),0,IF(M111>100,M111,G111*IF(M111>1,M111/100,M111))) -> 0 | O111: =IF(G111="","",G111*IF(L111="",0,IF(L111>1,L111/100,L111))+N111) | Q111: =IF(P111="","",IFERROR(VLOOKUP(P111,PARTNERS!$A$2:$B$30,2,0),"")) | R111: =IF(O111="","",IF(OR(P111="",Q111=""),0,(O111-N111)*IF(Q111>1,Q111/100,Q111))) | S111: =IF(O111="","",O111-R111) | U111: =IF(T111="","",IFERROR(VLOOKUP(T111,REPS!$A$2:$D$40,2,0),"")) | V111: =IF(O111="","",IF(U111="",0,O111*IF(U111>1,U111/100,U111))) | X111: =IF(W111="","",IFERROR(VLOOKUP(W111,REPS!$A$2:$D$40,3,0),"")) | Y111: =IF(O111="","",IF(X111="",0,O111*IF(X111>1,X111/100,X111))) | AA111: =IF(Z111="","",IFERROR(VLOOKUP(Z111,REPS!$A$2:$D$40,4,0),"")) | AB111: =IF(O111="","",IF(AA111="",0,O111*IF(AA111>1,AA111/100,AA111))) | AC111: =IF(O111="","",V111+Y111+AB111) | AD111: =IF(O111="","",O111-R111-AC111) | AG111: =IF(OR(AE111="",AE111=0),0,AE111*IF(U111="",0,IF(U111>1,U111/100,U111))) -> 0 | AH111: =IF(OR(AE111="",AE111=0),0,AE111*IF(X111="",0,IF(X111>1,X111/100,X111))) -> 0 | AI111: =IF(OR(AE111="",AE111=0),0,AE111*IF(AA111="",0,IF(AA111>1,AA111/100,AA111))) -> 0 | AJ111: =AG111+AH111+AI111 -> 0 | AK111: =IF(OR(AE111="",AE111=0),0,AE111-AJ111) -> 0 | AL111: =IF(AD111="","",AD111-AK111) | AM111: =IF(C111="","","Waiting for payment") | AP111: =IF(OR(C111="",I111="",K111=""),"",IF(K111="Monthly",EDATE(C111,ROUND(I111*SETTINGS!$I$8,0)),WORKDAY(C111,ROUND(I111*SETTINGS!$I$8,0)))) | AQ111: =IF(C111="","",IF(AND(AP111<>"",TODAY()>=AP111),"Refi Ready",IF(TODAY()-C111>=SETTINGS!$I$11,"Prospecting","Performing"))) | AR111: =IF(OR(C111="",I111="",K111=""),"",IF(K111="Monthly",EDATE(C111,I111),WORKDAY(C111,I111))) | AT111: =IF(C111="","",IF(AM111="Clawed Back","CLAWED",IF(TODAY()<=C111+SETTINGS!$I$2,"⚠ AT RISK","SAFE"))) | AW111: =AW110+IF(AND(C111<>"",AO111<>"",OR('REP COMMISSION'!$B$3="",T111='REP COMMISSION'!$B$3,W111='REP COMMISSION'!$B$3,Z111='REP COMMISSION'!$B$3)),1,0) -> 0 | AX111: =AX110+IF(AND(C111<>"",OR(F111="LOC - INITIAL",F111="CONSOLIDATION - UPFRONT COMM",F111="REVERSE - TOTAL FUNDING")),1,0) -> 0
A112: =IF(C112<>"","F"&COUNT($C$4:C112),"") | B112: =IF(OR(F112="LOC - INITIAL",F112="CONSOLIDATION - UPFRONT COMM",F112="REVERSE - TOTAL FUNDING"),A112,"") | J112: =IF(AND(G112<>"",H112<>""),G112*H112,"") | N112: =IF(OR(G112="",M112=""),0,IF(M112>100,M112,G112*IF(M112>1,M112/100,M112))) -> 0 | O112: =IF(G112="","",G112*IF(L112="",0,IF(L112>1,L112/100,L112))+N112) | Q112: =IF(P112="","",IFERROR(VLOOKUP(P112,PARTNERS!$A$2:$B$30,2,0),"")) | R112: =IF(O112="","",IF(OR(P112="",Q112=""),0,(O112-N112)*IF(Q112>1,Q112/100,Q112))) | S112: =IF(O112="","",O112-R112) | U112: =IF(T112="","",IFERROR(VLOOKUP(T112,REPS!$A$2:$D$40,2,0),"")) | V112: =IF(O112="","",IF(U112="",0,O112*IF(U112>1,U112/100,U112))) | X112: =IF(W112="","",IFERROR(VLOOKUP(W112,REPS!$A$2:$D$40,3,0),"")) | Y112: =IF(O112="","",IF(X112="",0,O112*IF(X112>1,X112/100,X112))) | AA112: =IF(Z112="","",IFERROR(VLOOKUP(Z112,REPS!$A$2:$D$40,4,0),"")) | AB112: =IF(O112="","",IF(AA112="",0,O112*IF(AA112>1,AA112/100,AA112))) | AC112: =IF(O112="","",V112+Y112+AB112) | AD112: =IF(O112="","",O112-R112-AC112) | AG112: =IF(OR(AE112="",AE112=0),0,AE112*IF(U112="",0,IF(U112>1,U112/100,U112))) -> 0 | AH112: =IF(OR(AE112="",AE112=0),0,AE112*IF(X112="",0,IF(X112>1,X112/100,X112))) -> 0 | AI112: =IF(OR(AE112="",AE112=0),0,AE112*IF(AA112="",0,IF(AA112>1,AA112/100,AA112))) -> 0 | AJ112: =AG112+AH112+AI112 -> 0 | AK112: =IF(OR(AE112="",AE112=0),0,AE112-AJ112) -> 0 | AL112: =IF(AD112="","",AD112-AK112) | AM112: =IF(C112="","","Waiting for payment") | AP112: =IF(OR(C112="",I112="",K112=""),"",IF(K112="Monthly",EDATE(C112,ROUND(I112*SETTINGS!$I$8,0)),WORKDAY(C112,ROUND(I112*SETTINGS!$I$8,0)))) | AQ112: =IF(C112="","",IF(AND(AP112<>"",TODAY()>=AP112),"Refi Ready",IF(TODAY()-C112>=SETTINGS!$I$11,"Prospecting","Performing"))) | AR112: =IF(OR(C112="",I112="",K112=""),"",IF(K112="Monthly",EDATE(C112,I112),WORKDAY(C112,I112))) | AT112: =IF(C112="","",IF(AM112="Clawed Back","CLAWED",IF(TODAY()<=C112+SETTINGS!$I$2,"⚠ AT RISK","SAFE"))) | AW112: =AW111+IF(AND(C112<>"",AO112<>"",OR('REP COMMISSION'!$B$3="",T112='REP COMMISSION'!$B$3,W112='REP COMMISSION'!$B$3,Z112='REP COMMISSION'!$B$3)),1,0) -> 0 | AX112: =AX111+IF(AND(C112<>"",OR(F112="LOC - INITIAL",F112="CONSOLIDATION - UPFRONT COMM",F112="REVERSE - TOTAL FUNDING")),1,0) -> 0
A113: =IF(C113<>"","F"&COUNT($C$4:C113),"") | B113: =IF(OR(F113="LOC - INITIAL",F113="CONSOLIDATION - UPFRONT COMM",F113="REVERSE - TOTAL FUNDING"),A113,"") | J113: =IF(AND(G113<>"",H113<>""),G113*H113,"") | N113: =IF(OR(G113="",M113=""),0,IF(M113>100,M113,G113*IF(M113>1,M113/100,M113))) -> 0 | O113: =IF(G113="","",G113*IF(L113="",0,IF(L113>1,L113/100,L113))+N113) | Q113: =IF(P113="","",IFERROR(VLOOKUP(P113,PARTNERS!$A$2:$B$30,2,0),"")) | R113: =IF(O113="","",IF(OR(P113="",Q113=""),0,(O113-N113)*IF(Q113>1,Q113/100,Q113))) | S113: =IF(O113="","",O113-R113) | U113: =IF(T113="","",IFERROR(VLOOKUP(T113,REPS!$A$2:$D$40,2,0),"")) | V113: =IF(O113="","",IF(U113="",0,O113*IF(U113>1,U113/100,U113))) | X113: =IF(W113="","",IFERROR(VLOOKUP(W113,REPS!$A$2:$D$40,3,0),"")) | Y113: =IF(O113="","",IF(X113="",0,O113*IF(X113>1,X113/100,X113))) | AA113: =IF(Z113="","",IFERROR(VLOOKUP(Z113,REPS!$A$2:$D$40,4,0),"")) | AB113: =IF(O113="","",IF(AA113="",0,O113*IF(AA113>1,AA113/100,AA113))) | AC113: =IF(O113="","",V113+Y113+AB113) | AD113: =IF(O113="","",O113-R113-AC113) | AG113: =IF(OR(AE113="",AE113=0),0,AE113*IF(U113="",0,IF(U113>1,U113/100,U113))) -> 0 | AH113: =IF(OR(AE113="",AE113=0),0,AE113*IF(X113="",0,IF(X113>1,X113/100,X113))) -> 0 | AI113: =IF(OR(AE113="",AE113=0),0,AE113*IF(AA113="",0,IF(AA113>1,AA113/100,AA113))) -> 0 | AJ113: =AG113+AH113+AI113 -> 0 | AK113: =IF(OR(AE113="",AE113=0),0,AE113-AJ113) -> 0 | AL113: =IF(AD113="","",AD113-AK113) | AM113: =IF(C113="","","Waiting for payment") | AP113: =IF(OR(C113="",I113="",K113=""),"",IF(K113="Monthly",EDATE(C113,ROUND(I113*SETTINGS!$I$8,0)),WORKDAY(C113,ROUND(I113*SETTINGS!$I$8,0)))) | AQ113: =IF(C113="","",IF(AND(AP113<>"",TODAY()>=AP113),"Refi Ready",IF(TODAY()-C113>=SETTINGS!$I$11,"Prospecting","Performing"))) | AR113: =IF(OR(C113="",I113="",K113=""),"",IF(K113="Monthly",EDATE(C113,I113),WORKDAY(C113,I113))) | AT113: =IF(C113="","",IF(AM113="Clawed Back","CLAWED",IF(TODAY()<=C113+SETTINGS!$I$2,"⚠ AT RISK","SAFE"))) | AW113: =AW112+IF(AND(C113<>"",AO113<>"",OR('REP COMMISSION'!$B$3="",T113='REP COMMISSION'!$B$3,W113='REP COMMISSION'!$B$3,Z113='REP COMMISSION'!$B$3)),1,0) -> 0 | AX113: =AX112+IF(AND(C113<>"",OR(F113="LOC - INITIAL",F113="CONSOLIDATION - UPFRONT COMM",F113="REVERSE - TOTAL FUNDING")),1,0) -> 0
A114: =IF(C114<>"","F"&COUNT($C$4:C114),"") | B114: =IF(OR(F114="LOC - INITIAL",F114="CONSOLIDATION - UPFRONT COMM",F114="REVERSE - TOTAL FUNDING"),A114,"") | J114: =IF(AND(G114<>"",H114<>""),G114*H114,"") | N114: =IF(OR(G114="",M114=""),0,IF(M114>100,M114,G114*IF(M114>1,M114/100,M114))) -> 0 | O114: =IF(G114="","",G114*IF(L114="",0,IF(L114>1,L114/100,L114))+N114) | Q114: =IF(P114="","",IFERROR(VLOOKUP(P114,PARTNERS!$A$2:$B$30,2,0),"")) | R114: =IF(O114="","",IF(OR(P114="",Q114=""),0,(O114-N114)*IF(Q114>1,Q114/100,Q114))) | S114: =IF(O114="","",O114-R114) | U114: =IF(T114="","",IFERROR(VLOOKUP(T114,REPS!$A$2:$D$40,2,0),"")) | V114: =IF(O114="","",IF(U114="",0,O114*IF(U114>1,U114/100,U114))) | X114: =IF(W114="","",IFERROR(VLOOKUP(W114,REPS!$A$2:$D$40,3,0),"")) | Y114: =IF(O114="","",IF(X114="",0,O114*IF(X114>1,X114/100,X114))) | AA114: =IF(Z114="","",IFERROR(VLOOKUP(Z114,REPS!$A$2:$D$40,4,0),"")) | AB114: =IF(O114="","",IF(AA114="",0,O114*IF(AA114>1,AA114/100,AA114))) | AC114: =IF(O114="","",V114+Y114+AB114) | AD114: =IF(O114="","",O114-R114-AC114) | AG114: =IF(OR(AE114="",AE114=0),0,AE114*IF(U114="",0,IF(U114>1,U114/100,U114))) -> 0 | AH114: =IF(OR(AE114="",AE114=0),0,AE114*IF(X114="",0,IF(X114>1,X114/100,X114))) -> 0 | AI114: =IF(OR(AE114="",AE114=0),0,AE114*IF(AA114="",0,IF(AA114>1,AA114/100,AA114))) -> 0 | AJ114: =AG114+AH114+AI114 -> 0 | AK114: =IF(OR(AE114="",AE114=0),0,AE114-AJ114) -> 0 | AL114: =IF(AD114="","",AD114-AK114) | AM114: =IF(C114="","","Waiting for payment") | AP114: =IF(OR(C114="",I114="",K114=""),"",IF(K114="Monthly",EDATE(C114,ROUND(I114*SETTINGS!$I$8,0)),WORKDAY(C114,ROUND(I114*SETTINGS!$I$8,0)))) | AQ114: =IF(C114="","",IF(AND(AP114<>"",TODAY()>=AP114),"Refi Ready",IF(TODAY()-C114>=SETTINGS!$I$11,"Prospecting","Performing"))) | AR114: =IF(OR(C114="",I114="",K114=""),"",IF(K114="Monthly",EDATE(C114,I114),WORKDAY(C114,I114))) | AT114: =IF(C114="","",IF(AM114="Clawed Back","CLAWED",IF(TODAY()<=C114+SETTINGS!$I$2,"⚠ AT RISK","SAFE"))) | AW114: =AW113+IF(AND(C114<>"",AO114<>"",OR('REP COMMISSION'!$B$3="",T114='REP COMMISSION'!$B$3,W114='REP COMMISSION'!$B$3,Z114='REP COMMISSION'!$B$3)),1,0) -> 0 | AX114: =AX113+IF(AND(C114<>"",OR(F114="LOC - INITIAL",F114="CONSOLIDATION - UPFRONT COMM",F114="REVERSE - TOTAL FUNDING")),1,0) -> 0
A115: =IF(C115<>"","F"&COUNT($C$4:C115),"") | B115: =IF(OR(F115="LOC - INITIAL",F115="CONSOLIDATION - UPFRONT COMM",F115="REVERSE - TOTAL FUNDING"),A115,"") | J115: =IF(AND(G115<>"",H115<>""),G115*H115,"") | N115: =IF(OR(G115="",M115=""),0,IF(M115>100,M115,G115*IF(M115>1,M115/100,M115))) -> 0 | O115: =IF(G115="","",G115*IF(L115="",0,IF(L115>1,L115/100,L115))+N115) | Q115: =IF(P115="","",IFERROR(VLOOKUP(P115,PARTNERS!$A$2:$B$30,2,0),"")) | R115: =IF(O115="","",IF(OR(P115="",Q115=""),0,(O115-N115)*IF(Q115>1,Q115/100,Q115))) | S115: =IF(O115="","",O115-R115) | U115: =IF(T115="","",IFERROR(VLOOKUP(T115,REPS!$A$2:$D$40,2,0),"")) | V115: =IF(O115="","",IF(U115="",0,O115*IF(U115>1,U115/100,U115))) | X115: =IF(W115="","",IFERROR(VLOOKUP(W115,REPS!$A$2:$D$40,3,0),"")) | Y115: =IF(O115="","",IF(X115="",0,O115*IF(X115>1,X115/100,X115))) | AA115: =IF(Z115="","",IFERROR(VLOOKUP(Z115,REPS!$A$2:$D$40,4,0),"")) | AB115: =IF(O115="","",IF(AA115="",0,O115*IF(AA115>1,AA115/100,AA115))) | AC115: =IF(O115="","",V115+Y115+AB115) | AD115: =IF(O115="","",O115-R115-AC115) | AG115: =IF(OR(AE115="",AE115=0),0,AE115*IF(U115="",0,IF(U115>1,U115/100,U115))) -> 0 | AH115: =IF(OR(AE115="",AE115=0),0,AE115*IF(X115="",0,IF(X115>1,X115/100,X115))) -> 0 | AI115: =IF(OR(AE115="",AE115=0),0,AE115*IF(AA115="",0,IF(AA115>1,AA115/100,AA115))) -> 0 | AJ115: =AG115+AH115+AI115 -> 0 | AK115: =IF(OR(AE115="",AE115=0),0,AE115-AJ115) -> 0 | AL115: =IF(AD115="","",AD115-AK115) | AM115: =IF(C115="","","Waiting for payment") | AP115: =IF(OR(C115="",I115="",K115=""),"",IF(K115="Monthly",EDATE(C115,ROUND(I115*SETTINGS!$I$8,0)),WORKDAY(C115,ROUND(I115*SETTINGS!$I$8,0)))) | AQ115: =IF(C115="","",IF(AND(AP115<>"",TODAY()>=AP115),"Refi Ready",IF(TODAY()-C115>=SETTINGS!$I$11,"Prospecting","Performing"))) | AR115: =IF(OR(C115="",I115="",K115=""),"",IF(K115="Monthly",EDATE(C115,I115),WORKDAY(C115,I115))) | AT115: =IF(C115="","",IF(AM115="Clawed Back","CLAWED",IF(TODAY()<=C115+SETTINGS!$I$2,"⚠ AT RISK","SAFE"))) | AW115: =AW114+IF(AND(C115<>"",AO115<>"",OR('REP COMMISSION'!$B$3="",T115='REP COMMISSION'!$B$3,W115='REP COMMISSION'!$B$3,Z115='REP COMMISSION'!$B$3)),1,0) -> 0 | AX115: =AX114+IF(AND(C115<>"",OR(F115="LOC - INITIAL",F115="CONSOLIDATION - UPFRONT COMM",F115="REVERSE - TOTAL FUNDING")),1,0) -> 0
A116: =IF(C116<>"","F"&COUNT($C$4:C116),"") | B116: =IF(OR(F116="LOC - INITIAL",F116="CONSOLIDATION - UPFRONT COMM",F116="REVERSE - TOTAL FUNDING"),A116,"") | J116: =IF(AND(G116<>"",H116<>""),G116*H116,"") | N116: =IF(OR(G116="",M116=""),0,IF(M116>100,M116,G116*IF(M116>1,M116/100,M116))) -> 0 | O116: =IF(G116="","",G116*IF(L116="",0,IF(L116>1,L116/100,L116))+N116) | Q116: =IF(P116="","",IFERROR(VLOOKUP(P116,PARTNERS!$A$2:$B$30,2,0),"")) | R116: =IF(O116="","",IF(OR(P116="",Q116=""),0,(O116-N116)*IF(Q116>1,Q116/100,Q116))) | S116: =IF(O116="","",O116-R116) | U116: =IF(T116="","",IFERROR(VLOOKUP(T116,REPS!$A$2:$D$40,2,0),"")) | V116: =IF(O116="","",IF(U116="",0,O116*IF(U116>1,U116/100,U116))) | X116: =IF(W116="","",IFERROR(VLOOKUP(W116,REPS!$A$2:$D$40,3,0),"")) | Y116: =IF(O116="","",IF(X116="",0,O116*IF(X116>1,X116/100,X116))) | AA116: =IF(Z116="","",IFERROR(VLOOKUP(Z116,REPS!$A$2:$D$40,4,0),"")) | AB116: =IF(O116="","",IF(AA116="",0,O116*IF(AA116>1,AA116/100,AA116))) | AC116: =IF(O116="","",V116+Y116+AB116) | AD116: =IF(O116="","",O116-R116-AC116) | AG116: =IF(OR(AE116="",AE116=0),0,AE116*IF(U116="",0,IF(U116>1,U116/100,U116))) -> 0 | AH116: =IF(OR(AE116="",AE116=0),0,AE116*IF(X116="",0,IF(X116>1,X116/100,X116))) -> 0 | AI116: =IF(OR(AE116="",AE116=0),0,AE116*IF(AA116="",0,IF(AA116>1,AA116/100,AA116))) -> 0 | AJ116: =AG116+AH116+AI116 -> 0 | AK116: =IF(OR(AE116="",AE116=0),0,AE116-AJ116) -> 0 | AL116: =IF(AD116="","",AD116-AK116) | AM116: =IF(C116="","","Waiting for payment") | AP116: =IF(OR(C116="",I116="",K116=""),"",IF(K116="Monthly",EDATE(C116,ROUND(I116*SETTINGS!$I$8,0)),WORKDAY(C116,ROUND(I116*SETTINGS!$I$8,0)))) | AQ116: =IF(C116="","",IF(AND(AP116<>"",TODAY()>=AP116),"Refi Ready",IF(TODAY()-C116>=SETTINGS!$I$11,"Prospecting","Performing"))) | AR116: =IF(OR(C116="",I116="",K116=""),"",IF(K116="Monthly",EDATE(C116,I116),WORKDAY(C116,I116))) | AT116: =IF(C116="","",IF(AM116="Clawed Back","CLAWED",IF(TODAY()<=C116+SETTINGS!$I$2,"⚠ AT RISK","SAFE"))) | AW116: =AW115+IF(AND(C116<>"",AO116<>"",OR('REP COMMISSION'!$B$3="",T116='REP COMMISSION'!$B$3,W116='REP COMMISSION'!$B$3,Z116='REP COMMISSION'!$B$3)),1,0) -> 0 | AX116: =AX115+IF(AND(C116<>"",OR(F116="LOC - INITIAL",F116="CONSOLIDATION - UPFRONT COMM",F116="REVERSE - TOTAL FUNDING")),1,0) -> 0
A117: =IF(C117<>"","F"&COUNT($C$4:C117),"") | B117: =IF(OR(F117="LOC - INITIAL",F117="CONSOLIDATION - UPFRONT COMM",F117="REVERSE - TOTAL FUNDING"),A117,"") | J117: =IF(AND(G117<>"",H117<>""),G117*H117,"") | N117: =IF(OR(G117="",M117=""),0,IF(M117>100,M117,G117*IF(M117>1,M117/100,M117))) -> 0 | O117: =IF(G117="","",G117*IF(L117="",0,IF(L117>1,L117/100,L117))+N117) | Q117: =IF(P117="","",IFERROR(VLOOKUP(P117,PARTNERS!$A$2:$B$30,2,0),"")) | R117: =IF(O117="","",IF(OR(P117="",Q117=""),0,(O117-N117)*IF(Q117>1,Q117/100,Q117))) | S117: =IF(O117="","",O117-R117) | U117: =IF(T117="","",IFERROR(VLOOKUP(T117,REPS!$A$2:$D$40,2,0),"")) | V117: =IF(O117="","",IF(U117="",0,O117*IF(U117>1,U117/100,U117))) | X117: =IF(W117="","",IFERROR(VLOOKUP(W117,REPS!$A$2:$D$40,3,0),"")) | Y117: =IF(O117="","",IF(X117="",0,O117*IF(X117>1,X117/100,X117))) | AA117: =IF(Z117="","",IFERROR(VLOOKUP(Z117,REPS!$A$2:$D$40,4,0),"")) | AB117: =IF(O117="","",IF(AA117="",0,O117*IF(AA117>1,AA117/100,AA117))) | AC117: =IF(O117="","",V117+Y117+AB117) | AD117: =IF(O117="","",O117-R117-AC117) | AG117: =IF(OR(AE117="",AE117=0),0,AE117*IF(U117="",0,IF(U117>1,U117/100,U117))) -> 0 | AH117: =IF(OR(AE117="",AE117=0),0,AE117*IF(X117="",0,IF(X117>1,X117/100,X117))) -> 0 | AI117: =IF(OR(AE117="",AE117=0),0,AE117*IF(AA117="",0,IF(AA117>1,AA117/100,AA117))) -> 0 | AJ117: =AG117+AH117+AI117 -> 0 | AK117: =IF(OR(AE117="",AE117=0),0,AE117-AJ117) -> 0 | AL117: =IF(AD117="","",AD117-AK117) | AM117: =IF(C117="","","Waiting for payment") | AP117: =IF(OR(C117="",I117="",K117=""),"",IF(K117="Monthly",EDATE(C117,ROUND(I117*SETTINGS!$I$8,0)),WORKDAY(C117,ROUND(I117*SETTINGS!$I$8,0)))) | AQ117: =IF(C117="","",IF(AND(AP117<>"",TODAY()>=AP117),"Refi Ready",IF(TODAY()-C117>=SETTINGS!$I$11,"Prospecting","Performing"))) | AR117: =IF(OR(C117="",I117="",K117=""),"",IF(K117="Monthly",EDATE(C117,I117),WORKDAY(C117,I117))) | AT117: =IF(C117="","",IF(AM117="Clawed Back","CLAWED",IF(TODAY()<=C117+SETTINGS!$I$2,"⚠ AT RISK","SAFE"))) | AW117: =AW116+IF(AND(C117<>"",AO117<>"",OR('REP COMMISSION'!$B$3="",T117='REP COMMISSION'!$B$3,W117='REP COMMISSION'!$B$3,Z117='REP COMMISSION'!$B$3)),1,0) -> 0 | AX117: =AX116+IF(AND(C117<>"",OR(F117="LOC - INITIAL",F117="CONSOLIDATION - UPFRONT COMM",F117="REVERSE - TOTAL FUNDING")),1,0) -> 0
... A205: =IF(C205<>"","F"&COUNT($C$4:C205),"") | B205: =IF(OR(F205="LOC - INITIAL",F205="CONSOLIDATION - UPFRONT COMM",F205="REVERSE - TOTAL FUNDING"),A205,"") | J205: =IF(AND(G205<>"",H205<>""),G205*H205,"") | N205: =IF(OR(G205="",M205=""),0,IF(M205>100,M205,G205*IF(M205>1,M205/100,M205))) -> 0 | O205: =IF(G205="","",G205*IF(L205="",0,IF(L205>1,L205/100,L205))+N205) | Q205: =IF(P205="","",IFERROR(VLOOKUP(P205,PARTNERS!$A$2:$B$30,2,0),"")) | R205: =IF(O205="","",IF(OR(P205="",Q205=""),0,(O205-N205)*IF(Q205>1,Q205/100,Q205))) | S205: =IF(O205="","",O205-R205) | U205: =IF(T205="","",IFERROR(VLOOKUP(T205,REPS!$A$2:$D$40,2,0),"")) | V205: =IF(O205="","",IF(U205="",0,O205*IF(U205>1,U205/100,U205))) | X205: =IF(W205="","",IFERROR(VLOOKUP(W205,REPS!$A$2:$D$40,3,0),"")) | Y205: =IF(O205="","",IF(X205="",0,O205*IF(X205>1,X205/100,X205))) | AA205: =IF(Z205="","",IFERROR(VLOOKUP(Z205,REPS!$A$2:$D$40,4,0),"")) | AB205: =IF(O205="","",IF(AA205="",0,O205*IF(AA205>1,AA205/100,AA205))) | AC205: =IF(O205="","",V205+Y205+AB205) | AD205: =IF(O205="","",O205-R205-AC205) | AG205: =IF(OR(AE205="",AE205=0),0,AE205*IF(U205="",0,IF(U205>1,U205/100,U205))) -> 0 | AH205: =IF(OR(AE205="",AE205=0),0,AE205*IF(X205="",0,IF(X205>1,X205/100,X205))) -> 0 | AI205: =IF(OR(AE205="",AE205=0),0,AE205*IF(AA205="",0,IF(AA205>1,AA205/100,AA205))) -> 0 | AJ205: =AG205+AH205+AI205 -> 0 | AK205: =IF(OR(AE205="",AE205=0),0,AE205-AJ205) -> 0 | AL205: =IF(AD205="","",AD205-AK205) | AM205: =IF(C205="","","Waiting for payment") | AP205: =IF(OR(C205="",I205="",K205=""),"",IF(K205="Monthly",EDATE(C205,ROUND(I205*SETTINGS!$I$8,0)),WORKDAY(C205,ROUND(I205*SETTINGS!$I$8,0)))) | AQ205: =IF(C205="","",IF(AND(AP205<>"",TODAY()>=AP205),"Refi Ready",IF(TODAY()-C205>=SETTINGS!$I$11,"Prospecting","Performing"))) | AR205: =IF(OR(C205="",I205="",K205=""),"",IF(K205="Monthly",EDATE(C205,I205),WORKDAY(C205,I205))) | AT205: =IF(C205="","",IF(AM205="Clawed Back","CLAWED",IF(TODAY()<=C205+SETTINGS!$I$2,"⚠ AT RISK","SAFE"))) | AW205: =AW204+IF(AND(C205<>"",AO205<>"",OR('REP COMMISSION'!$B$3="",T205='REP COMMISSION'!$B$3,W205='REP COMMISSION'!$B$3,Z205='REP COMMISSION'!$B$3)),1,0) -> 0 | AX205: =AX204+IF(AND(C205<>"",OR(F205="LOC - INITIAL",F205="CONSOLIDATION - UPFRONT COMM",F205="REVERSE - TOTAL FUNDING")),1,0) -> 0
A206: MAY TOTAL | D206: =COUNT(C106:C205)&" units" -> 0 units | G206: =SUM(G106:G205) -> 0 | N206: =SUM(N106:N205) -> 0 | O206: =SUM(O106:O205) -> 0 | R206: =SUM(R106:R205) -> 0 | S206: =SUM(S106:S205) -> 0 | AC206: =SUM(AC106:AC205) -> 0 | AD206: =SUM(AD106:AD205) -> 0 | AE206: =SUM(AE106:AE205) -> 0 | AJ206: =SUM(AJ106:AJ205) -> 0 | AK206: =SUM(AK106:AK205) -> 0 | AL206: =SUM(AL106:AL205) -> 0 | AW206: =AW205 -> 0 | AX206: =AX205 -> 0
A207: ▼ JUNE 2026 | AW207: =AW206 -> 0 | AX207: =AX206 -> 0
